<!-- BiRH Prototype 2 mounted on the UR10e Arm -->

<mujoco model="hand_ur10e">
  <compiler coordinate="local" angle="radian" meshdir="assets" autolimits="true"/>
  <option gravity="0 0 -9.81" integrator="RK4" timestep="0.0001">
    <!--<flag contact="enable" energy="enable"/>-->
  </option>

  <default>
    <default class="ur10e">
      <material specular="0.5" shininess="0.25"/>
      <joint axis="0 1 0" range="-6.28319 6.28319" armature="0.1"/>
      <position ctrlrange="-6.2831 6.2831"/>
      <general biastype="affine" ctrlrange="-6.2831 6.2831" gainprm="5000" biasprm="0 -5000 -500"/>
      <default class="size4">
        <joint damping="10"/>
        <general forcerange="-330 330"/>
      </default>
      <default class="size3">
        <joint damping="5"/>
        <general forcerange="-150 150"/>
        <default class="size3_limited">
          <joint range="-3.1415 3.1415"/>
          <general ctrlrange="-3.1415 3.1415"/>
        </default>
      </default>
      <default class="size2">
        <joint damping="2"/>
        <general forcerange="-56 56"/>
      </default>
      <default class="visual">
        <geom type="mesh" contype="0" conaffinity="0" group="2"/>
      </default>
      <default class="collision">
        <geom type="capsule" group="3"/>
        <default class="eef_collision">
          <geom type="cylinder"/>
        </default>
      </default>
      <site size="0.001" rgba="0.5 0.5 0.5 0.3" group="4"/>
    </default>
    
    <!-- Hand-specific defaults -->
    <default class="hand">
      <joint damping="5"/>
      <geom friction="1.0 0.1 0.001"/>
    </default>
  </default>

  <asset>
    <material class="ur10e" name="black" rgba="0.033 0.033 0.033 1"/>
    <material class="ur10e" name="jointgray" rgba="0.278 0.278 0.278 1"/>
    <material class="ur10e" name="linkgray" rgba="0.82 0.82 0.82 1"/>
    <material class="ur10e" name="urblue" rgba="0.49 0.678 0.8 1"/>

    <!-- UR10e meshes -->
    <mesh file="base_0.obj"/>
    <mesh file="base_1.obj"/>
    <mesh file="shoulder_0.obj"/>
    <mesh file="shoulder_1.obj"/>
    <mesh file="shoulder_2.obj"/>
    <mesh file="upperarm_0.obj"/>
    <mesh file="upperarm_1.obj"/>
    <mesh file="upperarm_2.obj"/>
    <mesh file="upperarm_3.obj"/>
    <mesh file="forearm_0.obj"/>
    <mesh file="forearm_1.obj"/>
    <mesh file="forearm_2.obj"/>
    <mesh file="forearm_3.obj"/>
    <mesh file="wrist1_0.obj"/>
    <mesh file="wrist1_1.obj"/>
    <mesh file="wrist1_2.obj"/>
    <mesh file="wrist2_0.obj"/>
    <mesh file="wrist2_1.obj"/>
    <mesh file="wrist2_2.obj"/>
    <mesh file="wrist3.obj"/>

    <!-- Mesh of all the objects taken from http://ycb-benchmarks.s3-website-us-east-1.amazonaws.com/ -->
    <mesh name="apple_mesh" file="apple.stl" scale="2 2 2"/>
    <mesh name="tuna_can_mesh" file="tuna_can.stl" scale="2 2 2"/>
    <mesh name="softball_mesh" file="softball.stl" scale="2 2 2"/>
    <mesh name="s_marker_mesh" file="s_marker.stl" scale="2 2 2"/>
    <mesh name="spatula_mesh" file="spatula.stl"/>
    <mesh name="chips_can_mesh" file="chips_can.stl" scale="2 2 2"/>
    <mesh name="cracker_box_mesh" file="cracker_box.stl" scale="2 2 2"/>
    <mesh name="pudding_mesh" file="pudding.stl" scale="2 2 2"/>
    <mesh name="pear_mesh" file="pear.stl" scale="2 2 2"/>
    <mesh name="pitcher_mesh" file="pitcher.stl" scale="2 2 2"/>
    <mesh name="bowl_mesh" file="bowl.stl" scale="2 2 2"/>
    <mesh name="skillet_mesh" file="skillet.stl" scale="0.5 0.5 0.5"/>
    <mesh name="plate_mesh" file="plate.stl" scale="0.5 0.5 0.5"/>
    <mesh name="power_drill_mesh" file="power_drill.stl" scale="2 2 2"/>
    <mesh name="keys_mesh" file="keys.stl" scale="0.5 0.5 0.5"/>
    <mesh name="l_marker_mesh" file="l_marker.stl" scale="2 2 2"/>
    <mesh name="screwdriver_mesh" file="screwdriver.stl" scale="2 2 2"/>
    <mesh name="s_clamp_mesh" file="s_clamp.stl" scale="2 2 2"/>
    <mesh name="soccer_ball_mesh" file="soccer_ball.stl" scale="2 2 2"/>
    <mesh name="golf_ball_mesh" file="golf_ball.stl" scale="2 2 2"/>
    <mesh name="cup_mesh" file="cup.stl" scale="2 2 2"/>
    

  </asset>

  <worldbody>
    <light name="spotlight" mode="targetbodycom" target="wrist_2_link" pos="0 -1 2"/>
    
    <body name="base" quat="0 0 0 -1" childclass="ur10e">
      <inertial mass="4.0" pos="0 0 0" diaginertia="0.0061063308908 0.0061063308908 0.01125"/>
      <geom mesh="base_0" material="black" class="visual"/>
      <geom mesh="base_1" material="jointgray" class="visual"/>
      <body name="shoulder_link" pos="0 0 0.181">
        <inertial pos="0 0 0" mass="7.778" diaginertia="0.0314743 0.0314743 0.0218756"/>
        <joint name="shoulder_pan_joint" class="size4" axis="0 0 1"/>
        <geom mesh="shoulder_0" material="urblue" class="visual"/>
        <geom mesh="shoulder_1" material="black" class="visual"/>
        <geom mesh="shoulder_2" material="jointgray" class="visual"/>
        <geom class="collision" size="0.078 0.08" pos="0 0 -0.05"/>
        <body name="upper_arm_link" pos="0 0.176 0" quat="1 0 1 0">
          <inertial pos="0 0 0.3065" mass="12.93" diaginertia="0.423074 0.423074 0.0363656"/>
          <joint name="shoulder_lift_joint" class="size4"/>
          <geom mesh="upperarm_0" material="black" class="visual"/>
          <geom mesh="upperarm_1" material="jointgray" class="visual"/>
          <geom mesh="upperarm_2" material="urblue" class="visual"/>
          <geom mesh="upperarm_3" material="linkgray" class="visual"/>
          <geom class="collision" pos="0 -0.05 0" quat="1 1 0 0" size="0.078 0.08"/>
          <geom class="collision" size="0.06 0.3" pos="0 0 0.3"/>
          <body name="forearm_link" pos="0 -0.137 0.613">
            <inertial pos="0 0 0.2855" mass="3.87" diaginertia="0.11059 0.11059 0.0108844"/>
            <joint name="elbow_joint" class="size3_limited"/>
            <geom mesh="forearm_0" material="urblue" class="visual"/>
            <geom mesh="forearm_1" material="black" class="visual"/>
            <geom mesh="forearm_2" material="jointgray" class="visual"/>
            <geom mesh="forearm_3" material="linkgray" class="visual"/>
            <geom class="collision" pos="0 0.08 0" quat="1 1 0 0" size="0.058 0.065"/>
            <geom class="collision" size="0.043 0.28" pos="0 0 0.29"/>
            <body name="wrist_1_link" pos="0 0 0.571" quat="1 0 1 0">
              <inertial pos="0 0.135 0" quat="0.5 0.5 -0.5 0.5" mass="1.96"
                diaginertia="0.0055125 0.00510825 0.00510825"/>
              <joint name="wrist_1_joint" class="size2"/>
              <geom mesh="wrist1_0" material="black" class="visual"/>
              <geom mesh="wrist1_1" material="urblue" class="visual"/>
              <geom mesh="wrist1_2" material="jointgray" class="visual"/>
              <geom class="collision" pos="0 0.06 0" quat="1 1 0 0" size="0.05 0.07"/>
              <body name="wrist_2_link" pos="0 0.135 0">
                <inertial pos="0 0 0.12" quat="0.5 0.5 -0.5 0.5" mass="1.96"
                  diaginertia="0.0055125 0.00510825 0.00510825"/>
                <joint name="wrist_2_joint" axis="0 0 1" class="size2"/>
                <geom mesh="wrist2_0" material="black" class="visual"/>
                <geom mesh="wrist2_1" material="urblue" class="visual"/>
                <geom mesh="wrist2_2" material="jointgray" class="visual"/>
                <geom class="collision" size="0.046 0.065" pos="0 0 0.05"/>
                <geom class="collision" pos="0 0.028 0.12" quat="1 1 0 0" size="0.046 0.043"/>
                <body name="wrist_3_link" pos="0 0 0.12">
                  <inertial pos="0 0.092 0" quat="0 1 -1 0" mass="0.202"
                    diaginertia="0.000204525 0.000144346 0.000144346"/>
                  <joint name="wrist_3_joint" class="size2"/>
                  <geom material="linkgray" mesh="wrist3" class="visual"/>
                  <geom class="eef_collision" pos="0 0.097 0" quat="1 1 0 0" size="0.046 0.02"/>
                  <site name="attachment_site" pos="0 0.1 0" quat="-1 1 0 0"/>
                    <!--  Hand  -->
                  <body name="hand" pos="0 0.12 0" quat="0.707 -0.707 0 0">
                    <!--<joint name="wrist" type="hinge" damping="100" axis="1 0 0"/>-->
                    <geom name="palm" type="cylinder" pos="0 0 0" size="0.05 0.0125"/>

                    <!--  Finger 1  -->
                    <body name="finger1_pp" pos="0 .05 0">
                      <joint name="mpj1" type="hinge" axis="1 0 0" damping="5" range="0 1.571"/>
                      <geom name="pp1" type="capsule" fromto="0 0 0 0 .075 0" size="0.0125" mass=".1"/>
                        <body name="finger1_mp" pos="0 .075 0">
                          <joint name="pipj1" type="hinge" axis="1 0 0" damping="5" range="0 1.571"/>
                          <geom name="mp1" type="capsule" fromto="0 0 0 0 .05 0" size="0.0125" mass=".1"/>
                            <geom name="finger1_pad" type="box" pos="0 0.04 0" size="0.01 0.0075 0.005" 
                                  friction="1.5 0.1 0.001" rgba="0.8 0.6 0.4 1"/>
                        </body>
                    </body>

                    <!--  Finger 2  -->
                    <body name="finger2_pp" pos="-0.03535 0.03535 0">
                      <joint name="mpj2" type="hinge" axis="1 1 0" damping="5" range="0 1.571"/>
                      <geom name="pp2" type="capsule" fromto="0 0 0 -.053 .053 0" size="0.0125" mass=".1"/>
                        <body name="finger2_mp" pos="-.053 .053 0">
                          <joint name="pipj2" type="hinge" axis="1 1 0" damping="5" range="0 1.571"/>
                          <geom name="mp2" type="capsule" fromto="0 0 0 -0.03535 0.03535 0" size="0.0125" mass=".1"/>
                        </body>
                    </body>

                    <!-- Thumb -->
                    <body name="thumb_pp" pos="0.03535 -0.03535 0">
                      <joint name="mpjt" type="hinge" axis="1 1 0" damping="5" range="0 1.571"/>
                      <joint name="abd_add" type="hinge" axis="0 0 1" damping="5" range="-0.5237 0.5237"/>
                      <geom name="ppt" type="capsule" fromto="0 0 0 .053 -.053 0" size="0.0125" mass=".1"/>
                        <body name="fingert_mp" pos=".053 -.053 0">
                          <joint name="pipjt" type="hinge" axis="1 1 0" damping="5" range="-1.571 0"/>
                          <geom name="mpt" type="capsule" fromto="0 0 0 0.03535 -0.03535 0" size="0.0125" mass=".1"/>
                        </body>
                    </body>

                    
                  </body>
                        
                </body>
              </body>
            </body>
          </body>
        </body>
      </body>
    </body>

    <!-- Objects for grasping -->
    <body name="apple" pos="-1.5 0.5 0">
      <freejoint/>
      <geom name="apple_g" type="mesh" mesh="apple_mesh" mass="0.2"/>
    </body>

    <body name="tuna" pos="-1 0.5 0">
      <freejoint/>
      <geom name="tuna_g" type="mesh" mesh="tuna_can_mesh" mass="0.2"/>
    </body>

    <body name="softball" pos="-0.5 0.5 0">
      <freejoint/>
      <geom name="softball_g" type="mesh" mesh="softball_mesh" mass="0.2"/>
    </body>

    <body name="s_marker" pos="0 0.5 0">
      <freejoint/>
      <geom name="s_marker_g" type="mesh" mesh="s_marker_mesh" mass="0.2"/>
    </body>

    <body name="spatula" pos="0.5 0.5 0">
      <freejoint/>
      <geom name="spatula_g" type="mesh" mesh="spatula_mesh" mass="0.2"/>
    </body>

    <body name="chips_can" pos="1 0.5 0">
      <freejoint/>
      <geom name="chips_can_g" type="mesh" mesh="chips_can_mesh" mass="0.2"/>
    </body>

    <body name="cracker_box" pos="1.5 0.5 0">
      <freejoint/>
      <geom name="cracker_box_g" type="mesh" mesh="cracker_box_mesh" mass="0.2"/>
    </body>

    <body name="pudding" pos="2 0.5 0">
      <freejoint/>
      <geom name="pudding_g" type="mesh" mesh="pudding_mesh" mass="0.2"/>
    </body>

    <body name="pear" pos="-1.5 1 0">
      <freejoint/>
      <geom name="pear_g" type="mesh" mesh="pear_mesh" mass="0.2"/>
    </body>

    <body name="pitcher" pos="-1 1 0">
      <freejoint/>
      <geom name="pitcher_g" type="mesh" mesh="pitcher_mesh" mass="0.2"/>
    </body>

    <body name="bowl" pos="-.5 1 0">
      <freejoint/>
      <geom name="bowl_g" type="mesh" mesh="bowl_mesh" mass="0.2"/>
    </body>

    <body name="skillet" pos="0 1 0">
      <freejoint/>
      <geom name="skillet_g" type="mesh" mesh="skillet_mesh" mass="0.2"/>
    </body>

    <body name="plate" pos=".5 1 0">
      <freejoint/>
      <geom name="plate_g" type="mesh" mesh="plate_mesh" mass="0.2"/>
    </body>

    <body name="power_drill" pos="1 1 0">
      <freejoint/>
      <geom name="power_drill_g" type="mesh" mesh="power_drill_mesh" mass="0.2"/>
    </body>

    <body name="keys" pos="1.5 1 0">
      <freejoint/>
      <geom name="keys_g" type="mesh" mesh="keys_mesh" mass="0.2"/>
    </body>

    <body name="l_marker" pos="2 1 0">
      <freejoint/>
      <geom name="l_marker_g" type="mesh" mesh="l_marker_mesh" mass="0.2"/>
    </body>

    <body name="screwdriver" pos="-1.5 1.5 0">
      <freejoint/>
      <geom name="screwdriver_g" type="mesh" mesh="screwdriver_mesh" mass="0.2"/>
    </body>

    <body name="s_clamp" pos="-1 1.5 0">
      <freejoint/>
      <geom name="s_clamp_g" type="mesh" mesh="s_clamp_mesh" mass="0.2"/>
    </body>

    <body name="soccer_ball" pos="-.5 1.5 0">
      <freejoint/>
      <geom name="soccer_ball_g" type="mesh" mesh="soccer_ball_mesh" mass="0.2"/>
    </body>

    <body name="golf_ball" pos="0 1.5 0">
      <freejoint/>
      <geom name="golf_ball_g" type="mesh" mesh="golf_ball_mesh" mass="0.2"/>
    </body>

    <body name="cup" pos=".5 1.5 0">
      <freejoint/>
      <geom name="cup_g" type="mesh" mesh="cup_mesh" mass="0.2"/>
    </body>


  </worldbody>

  <actuator>
    <!-- UR10e actuators -->
    <general class="size4" name="shoulder_pan" joint="shoulder_pan_joint"/>
    <general class="size4" name="shoulder_lift" joint="shoulder_lift_joint"/>
    <general class="size3_limited" name="elbow" joint="elbow_joint"/>
    <general class="size2" name="wrist_1" joint="wrist_1_joint"/>
    <general class="size2" name="wrist_2" joint="wrist_2_joint"/>
    <general class="size2" name="wrist_3" joint="wrist_3_joint"/>

    <!-- Hand actuators -->
    <position name="mpj1_motor" joint="mpj1" kp="200" ctrlrange="0 1.571"/>
    <position name="pipj1_motor" joint="pipj1" kp="100" ctrlrange="0 1.571"/>
    <position name="mpj2_motor" joint="mpj2" kp="200" ctrlrange="0 1.571"/>
    <position name="pipj2_motor" joint="pipj2" kp="100" ctrlrange="0 1.571"/>
    <position name="mpjt_motor" joint="mpjt" kp="2000" ctrlrange="-1.571 0"/>
    <position name="abd_add_motor" joint="abd_add" kp="5000" ctrlrange="-1.2 1.2"/>
    <position name="pipjt_motor" joint="pipjt" kp="1000" ctrlrange="-1.571 0"/>
  </actuator>

 <!-- <keyframe>
    <key name="home" qpos="-1.5708 -1.5708 1.5708 -1.5708 -1.5708 0 0 0 0 0 0 0 0" 
         ctrl="-1.5708 -1.5708 1.5708 -1.5708 -1.5708 0 0 0 0 0 0 0 0"/>
  </keyframe>-->
</mujoco>